[2023-01-05T10:04:50.856+0000] {taskinstance.py:1087} INFO - Dependencies all met for <TaskInstance: import_full_database.import_data manual__2023-01-05T10:04:49.723980+00:00 [queued]>
[2023-01-05T10:04:50.875+0000] {taskinstance.py:1087} INFO - Dependencies all met for <TaskInstance: import_full_database.import_data manual__2023-01-05T10:04:49.723980+00:00 [queued]>
[2023-01-05T10:04:50.875+0000] {taskinstance.py:1283} INFO - 
--------------------------------------------------------------------------------
[2023-01-05T10:04:50.875+0000] {taskinstance.py:1284} INFO - Starting attempt 1 of 1
[2023-01-05T10:04:50.875+0000] {taskinstance.py:1285} INFO - 
--------------------------------------------------------------------------------
[2023-01-05T10:04:50.929+0000] {taskinstance.py:1304} INFO - Executing <Task(PythonOperator): import_data> on 2023-01-05 10:04:49.723980+00:00
[2023-01-05T10:04:50.937+0000] {standard_task_runner.py:55} INFO - Started process 11144 to run task
[2023-01-05T10:04:50.946+0000] {standard_task_runner.py:82} INFO - Running: ['***', 'tasks', 'run', 'import_full_database', 'import_data', 'manual__2023-01-05T10:04:49.723980+00:00', '--job-id', '213', '--raw', '--subdir', 'DAGS_FOLDER/import_full_database.py', '--cfg-path', '/tmp/tmpnhbvjlr0']
[2023-01-05T10:04:50.949+0000] {standard_task_runner.py:83} INFO - Job 213: Subtask import_data
[2023-01-05T10:04:51.168+0000] {task_command.py:389} INFO - Running <TaskInstance: import_full_database.import_data manual__2023-01-05T10:04:49.723980+00:00 [running]> on host d84d515babd0
[2023-01-05T10:04:51.360+0000] {taskinstance.py:1513} INFO - Exporting the following env vars:
AIRFLOW_CTX_DAG_OWNER=***
AIRFLOW_CTX_DAG_ID=import_full_database
AIRFLOW_CTX_TASK_ID=import_data
AIRFLOW_CTX_EXECUTION_DATE=2023-01-05T10:04:49.723980+00:00
AIRFLOW_CTX_TRY_NUMBER=1
AIRFLOW_CTX_DAG_RUN_ID=manual__2023-01-05T10:04:49.723980+00:00
[2023-01-05T10:06:16.573+0000] {taskinstance.py:1772} ERROR - Task failed with exception
Traceback (most recent call last):
  File "/home/airflow/.local/lib/python3.7/site-packages/airflow/operators/python.py", line 175, in execute
    return_value = self.execute_callable()
  File "/home/airflow/.local/lib/python3.7/site-packages/airflow/operators/python.py", line 192, in execute_callable
    return self.python_callable(*self.op_args, **self.op_kwargs)
  File "/opt/airflow/dags/import_full_database.py", line 80, in csv_to_db
    industry_financial_health = pd.read_csv('/opt/airflow/data/full data/Industry Financial Rating.csv')
  File "/home/airflow/.local/lib/python3.7/site-packages/pandas/util/_decorators.py", line 311, in wrapper
    return func(*args, **kwargs)
  File "/home/airflow/.local/lib/python3.7/site-packages/pandas/io/parsers/readers.py", line 586, in read_csv
    return _read(filepath_or_buffer, kwds)
  File "/home/airflow/.local/lib/python3.7/site-packages/pandas/io/parsers/readers.py", line 482, in _read
    parser = TextFileReader(filepath_or_buffer, **kwds)
  File "/home/airflow/.local/lib/python3.7/site-packages/pandas/io/parsers/readers.py", line 811, in __init__
    self._engine = self._make_engine(self.engine)
  File "/home/airflow/.local/lib/python3.7/site-packages/pandas/io/parsers/readers.py", line 1040, in _make_engine
    return mapping[engine](self.f, **self.options)  # type: ignore[call-arg]
  File "/home/airflow/.local/lib/python3.7/site-packages/pandas/io/parsers/c_parser_wrapper.py", line 51, in __init__
    self._open_handles(src, kwds)
  File "/home/airflow/.local/lib/python3.7/site-packages/pandas/io/parsers/base_parser.py", line 229, in _open_handles
    errors=kwds.get("encoding_errors", "strict"),
  File "/home/airflow/.local/lib/python3.7/site-packages/pandas/io/common.py", line 707, in get_handle
    newline="",
FileNotFoundError: [Errno 2] No such file or directory: '/opt/airflow/data/full data/Industry Financial Rating.csv'
[2023-01-05T10:06:16.580+0000] {taskinstance.py:1327} INFO - Marking task as FAILED. dag_id=import_full_database, task_id=import_data, execution_date=20230105T100449, start_date=20230105T100450, end_date=20230105T100616
[2023-01-05T10:06:16.623+0000] {standard_task_runner.py:105} ERROR - Failed to execute job 213 for task import_data ([Errno 2] No such file or directory: '/opt/airflow/data/full data/Industry Financial Rating.csv'; 11144)
[2023-01-05T10:06:16.671+0000] {local_task_job.py:159} INFO - Task exited with return code 1
[2023-01-05T10:06:16.697+0000] {taskinstance.py:2582} INFO - 0 downstream tasks scheduled from follow-on schedule check
