[2022-12-28T08:42:39.373+0000] {taskinstance.py:1087} INFO - Dependencies all met for <TaskInstance: import_through_csv_v1.create_table manual__2022-12-28T08:42:34.493655+00:00 [queued]>
[2022-12-28T08:42:39.384+0000] {taskinstance.py:1087} INFO - Dependencies all met for <TaskInstance: import_through_csv_v1.create_table manual__2022-12-28T08:42:34.493655+00:00 [queued]>
[2022-12-28T08:42:39.384+0000] {taskinstance.py:1283} INFO - 
--------------------------------------------------------------------------------
[2022-12-28T08:42:39.384+0000] {taskinstance.py:1284} INFO - Starting attempt 1 of 1
[2022-12-28T08:42:39.384+0000] {taskinstance.py:1285} INFO - 
--------------------------------------------------------------------------------
[2022-12-28T08:42:39.695+0000] {taskinstance.py:1304} INFO - Executing <Task(PostgresOperator): create_table> on 2022-12-28 08:42:34.493655+00:00
[2022-12-28T08:42:39.836+0000] {standard_task_runner.py:55} INFO - Started process 478 to run task
[2022-12-28T08:42:39.841+0000] {standard_task_runner.py:82} INFO - Running: ['***', 'tasks', 'run', 'import_through_csv_v1', 'create_table', 'manual__2022-12-28T08:42:34.493655+00:00', '--job-id', '109', '--raw', '--subdir', 'DAGS_FOLDER/import_by_csv.py', '--cfg-path', '/tmp/tmp1280pgkh']
[2022-12-28T08:42:39.843+0000] {standard_task_runner.py:83} INFO - Job 109: Subtask create_table
[2022-12-28T08:42:40.226+0000] {task_command.py:389} INFO - Running <TaskInstance: import_through_csv_v1.create_table manual__2022-12-28T08:42:34.493655+00:00 [running]> on host f68f12b30799
[2022-12-28T08:42:40.919+0000] {taskinstance.py:1513} INFO - Exporting the following env vars:
AIRFLOW_CTX_DAG_OWNER=***
AIRFLOW_CTX_DAG_ID=import_through_csv_v1
AIRFLOW_CTX_TASK_ID=create_table
AIRFLOW_CTX_EXECUTION_DATE=2022-12-28T08:42:34.493655+00:00
AIRFLOW_CTX_TRY_NUMBER=1
AIRFLOW_CTX_DAG_RUN_ID=manual__2022-12-28T08:42:34.493655+00:00
[2022-12-28T08:42:40.920+0000] {sql.py:253} INFO - Executing: 
            CREATE TABLE IF NOT EXISTS test_table (
                ticker varchar(3),
                year integer,
                quarter integer,
                invest_cost integer,
                from_invest integer,
                from_financial integer,
                from_sale integer,
                free_cash_flow double precision,
                PRIMARY KEY (ticker, year, quarter),
                FOREIGN KEY (ticker) REFERENCES listing_companies (ticker)
            );
        
[2022-12-28T08:42:40.929+0000] {base.py:73} INFO - Using connection ID 'financial_database' for task execution.
[2022-12-28T08:42:41.234+0000] {base.py:73} INFO - Using connection ID 'financial_database' for task execution.
[2022-12-28T08:42:41.250+0000] {sql.py:364} INFO - Running statement: 
            CREATE TABLE IF NOT EXISTS test_table (
                ticker varchar(3),
                year integer,
                quarter integer,
                invest_cost integer,
                from_invest integer,
                from_financial integer,
                from_sale integer,
                free_cash_flow double precision,
                PRIMARY KEY (ticker, year, quarter),
                FOREIGN KEY (ticker) REFERENCES listing_companies (ticker)
            );
        , parameters: None
[2022-12-28T08:42:42.064+0000] {taskinstance.py:1772} ERROR - Task failed with exception
Traceback (most recent call last):
  File "/home/airflow/.local/lib/python3.7/site-packages/airflow/providers/common/sql/operators/sql.py", line 261, in execute
    return_last=self.return_last,
  File "/home/airflow/.local/lib/python3.7/site-packages/airflow/providers/common/sql/hooks/sql.py", line 338, in run
    self._run_command(cur, sql_statement, parameters)
  File "/home/airflow/.local/lib/python3.7/site-packages/airflow/providers/common/sql/hooks/sql.py", line 369, in _run_command
    cur.execute(sql_statement)
psycopg2.errors.UniqueViolation: duplicate key value violates unique constraint "pg_type_typname_nsp_index"
DETAIL:  Key (typname, typnamespace)=(test_table, 2200) already exists.

[2022-12-28T08:42:42.072+0000] {taskinstance.py:1327} INFO - Marking task as FAILED. dag_id=import_through_csv_v1, task_id=create_table, execution_date=20221228T084234, start_date=20221228T084239, end_date=20221228T084242
[2022-12-28T08:42:42.302+0000] {standard_task_runner.py:105} ERROR - Failed to execute job 109 for task create_table (duplicate key value violates unique constraint "pg_type_typname_nsp_index"
DETAIL:  Key (typname, typnamespace)=(test_table, 2200) already exists.
; 478)
[2022-12-28T08:42:42.336+0000] {local_task_job.py:159} INFO - Task exited with return code 1
[2022-12-28T08:42:42.376+0000] {taskinstance.py:2582} INFO - 0 downstream tasks scheduled from follow-on schedule check
