[2023-01-01T05:36:23.524+0000] {taskinstance.py:1087} INFO - Dependencies all met for <TaskInstance: import_to_test_table_v1.get_cash_flow_data scheduled__2022-12-31T00:00:00+00:00 [queued]>
[2023-01-01T05:36:23.532+0000] {taskinstance.py:1087} INFO - Dependencies all met for <TaskInstance: import_to_test_table_v1.get_cash_flow_data scheduled__2022-12-31T00:00:00+00:00 [queued]>
[2023-01-01T05:36:23.533+0000] {taskinstance.py:1283} INFO - 
--------------------------------------------------------------------------------
[2023-01-01T05:36:23.533+0000] {taskinstance.py:1284} INFO - Starting attempt 1 of 1
[2023-01-01T05:36:23.533+0000] {taskinstance.py:1285} INFO - 
--------------------------------------------------------------------------------
[2023-01-01T05:36:23.589+0000] {taskinstance.py:1304} INFO - Executing <Task(PythonOperator): get_cash_flow_data> on 2022-12-31 00:00:00+00:00
[2023-01-01T05:36:23.593+0000] {standard_task_runner.py:55} INFO - Started process 373 to run task
[2023-01-01T05:36:23.596+0000] {standard_task_runner.py:82} INFO - Running: ['***', 'tasks', 'run', 'import_to_test_table_v1', 'get_cash_flow_data', 'scheduled__2022-12-31T00:00:00+00:00', '--job-id', '127', '--raw', '--subdir', 'DAGS_FOLDER/import_to_test_table.py', '--cfg-path', '/tmp/tmpijxdxuyk']
[2023-01-01T05:36:23.598+0000] {standard_task_runner.py:83} INFO - Job 127: Subtask get_cash_flow_data
[2023-01-01T05:36:23.682+0000] {task_command.py:389} INFO - Running <TaskInstance: import_to_test_table_v1.get_cash_flow_data scheduled__2022-12-31T00:00:00+00:00 [running]> on host 9b696cbf6f55
[2023-01-01T05:36:23.799+0000] {taskinstance.py:1513} INFO - Exporting the following env vars:
AIRFLOW_CTX_DAG_OWNER=***
AIRFLOW_CTX_DAG_ID=import_to_test_table_v1
AIRFLOW_CTX_TASK_ID=get_cash_flow_data
AIRFLOW_CTX_EXECUTION_DATE=2022-12-31T00:00:00+00:00
AIRFLOW_CTX_TRY_NUMBER=1
AIRFLOW_CTX_DAG_RUN_ID=scheduled__2022-12-31T00:00:00+00:00
[2023-01-01T05:36:31.414+0000] {taskinstance.py:1772} ERROR - Task failed with exception
Traceback (most recent call last):
  File "/home/airflow/.local/lib/python3.7/site-packages/airflow/operators/python.py", line 175, in execute
    return_value = self.execute_callable()
  File "/home/airflow/.local/lib/python3.7/site-packages/airflow/operators/python.py", line 192, in execute_callable
    return self.python_callable(*self.op_args, **self.op_kwargs)
  File "/opt/airflow/dags/import_to_test_table.py", line 60, in get_cash_flow_data
    cash_flow.to_csv('/opt/airflow/data/Cash Flow.csv', sep=',', encoding='utf-8')
  File "/home/airflow/.local/lib/python3.7/site-packages/pandas/core/generic.py", line 3482, in to_csv
    storage_options=storage_options,
  File "/home/airflow/.local/lib/python3.7/site-packages/pandas/io/formats/format.py", line 1105, in to_csv
    csv_formatter.save()
  File "/home/airflow/.local/lib/python3.7/site-packages/pandas/io/formats/csvs.py", line 243, in save
    storage_options=self.storage_options,
  File "/home/airflow/.local/lib/python3.7/site-packages/pandas/io/common.py", line 707, in get_handle
    newline="",
PermissionError: [Errno 13] Permission denied: '/opt/airflow/data/Cash Flow.csv'
[2023-01-01T05:36:31.428+0000] {taskinstance.py:1327} INFO - Marking task as FAILED. dag_id=import_to_test_table_v1, task_id=get_cash_flow_data, execution_date=20221231T000000, start_date=20230101T053623, end_date=20230101T053631
[2023-01-01T05:36:31.517+0000] {standard_task_runner.py:105} ERROR - Failed to execute job 127 for task get_cash_flow_data ([Errno 13] Permission denied: '/opt/airflow/data/Cash Flow.csv'; 373)
[2023-01-01T05:36:31.546+0000] {local_task_job.py:159} INFO - Task exited with return code 1
[2023-01-01T05:36:31.566+0000] {taskinstance.py:2582} INFO - 0 downstream tasks scheduled from follow-on schedule check
