[2023-01-05T02:14:04.111+0000] {taskinstance.py:1087} INFO - Dependencies all met for <TaskInstance: ticker_to_txt.ticker_to_txt manual__2023-01-05T02:13:46.683626+00:00 [queued]>
[2023-01-05T02:14:04.122+0000] {taskinstance.py:1087} INFO - Dependencies all met for <TaskInstance: ticker_to_txt.ticker_to_txt manual__2023-01-05T02:13:46.683626+00:00 [queued]>
[2023-01-05T02:14:04.123+0000] {taskinstance.py:1283} INFO - 
--------------------------------------------------------------------------------
[2023-01-05T02:14:04.123+0000] {taskinstance.py:1284} INFO - Starting attempt 1 of 1
[2023-01-05T02:14:04.123+0000] {taskinstance.py:1285} INFO - 
--------------------------------------------------------------------------------
[2023-01-05T02:14:04.172+0000] {taskinstance.py:1304} INFO - Executing <Task(PythonOperator): ticker_to_txt> on 2023-01-05 02:13:46.683626+00:00
[2023-01-05T02:14:04.177+0000] {standard_task_runner.py:55} INFO - Started process 79886 to run task
[2023-01-05T02:14:04.181+0000] {standard_task_runner.py:82} INFO - Running: ['***', 'tasks', 'run', 'ticker_to_txt', 'ticker_to_txt', 'manual__2023-01-05T02:13:46.683626+00:00', '--job-id', '182', '--raw', '--subdir', 'DAGS_FOLDER/ticker.py', '--cfg-path', '/tmp/tmp_7oe7gss']
[2023-01-05T02:14:04.183+0000] {standard_task_runner.py:83} INFO - Job 182: Subtask ticker_to_txt
[2023-01-05T02:14:04.285+0000] {task_command.py:389} INFO - Running <TaskInstance: ticker_to_txt.ticker_to_txt manual__2023-01-05T02:13:46.683626+00:00 [running]> on host a247bc2e8348
[2023-01-05T02:14:04.480+0000] {taskinstance.py:1513} INFO - Exporting the following env vars:
AIRFLOW_CTX_DAG_OWNER=***
AIRFLOW_CTX_DAG_ID=ticker_to_txt
AIRFLOW_CTX_TASK_ID=ticker_to_txt
AIRFLOW_CTX_EXECUTION_DATE=2023-01-05T02:13:46.683626+00:00
AIRFLOW_CTX_TRY_NUMBER=1
AIRFLOW_CTX_DAG_RUN_ID=manual__2023-01-05T02:13:46.683626+00:00
[2023-01-05T02:14:14.614+0000] {taskinstance.py:1772} ERROR - Task failed with exception
Traceback (most recent call last):
  File "/home/airflow/.local/lib/python3.7/site-packages/urllib3/connection.py", line 175, in _new_conn
    (self._dns_host, self.port), self.timeout, **extra_kw
  File "/home/airflow/.local/lib/python3.7/site-packages/urllib3/util/connection.py", line 72, in create_connection
    for res in socket.getaddrinfo(host, port, family, socket.SOCK_STREAM):
  File "/usr/local/lib/python3.7/socket.py", line 752, in getaddrinfo
    for res in _socket.getaddrinfo(host, port, family, type, proto, flags):
socket.gaierror: [Errno -3] Temporary failure in name resolution

During handling of the above exception, another exception occurred:

Traceback (most recent call last):
  File "/home/airflow/.local/lib/python3.7/site-packages/urllib3/connectionpool.py", line 710, in urlopen
    chunked=chunked,
  File "/home/airflow/.local/lib/python3.7/site-packages/urllib3/connectionpool.py", line 386, in _make_request
    self._validate_conn(conn)
  File "/home/airflow/.local/lib/python3.7/site-packages/urllib3/connectionpool.py", line 1042, in _validate_conn
    conn.connect()
  File "/home/airflow/.local/lib/python3.7/site-packages/urllib3/connection.py", line 358, in connect
    self.sock = conn = self._new_conn()
  File "/home/airflow/.local/lib/python3.7/site-packages/urllib3/connection.py", line 187, in _new_conn
    self, "Failed to establish a new connection: %s" % e
urllib3.exceptions.NewConnectionError: <urllib3.connection.HTTPSConnection object at 0x7f6905fa6390>: Failed to establish a new connection: [Errno -3] Temporary failure in name resolution

During handling of the above exception, another exception occurred:

Traceback (most recent call last):
  File "/home/airflow/.local/lib/python3.7/site-packages/requests/adapters.py", line 499, in send
    timeout=timeout,
  File "/home/airflow/.local/lib/python3.7/site-packages/urllib3/connectionpool.py", line 788, in urlopen
    method, url, error=e, _pool=self, _stacktrace=sys.exc_info()[2]
  File "/home/airflow/.local/lib/python3.7/site-packages/urllib3/util/retry.py", line 592, in increment
    raise MaxRetryError(_pool, url, error or ResponseError(cause))
urllib3.exceptions.MaxRetryError: HTTPSConnectionPool(host='fiin-core.ssi.com.vn', port=443): Max retries exceeded with url: /Master/GetListOrganization?language=vi (Caused by NewConnectionError('<urllib3.connection.HTTPSConnection object at 0x7f6905fa6390>: Failed to establish a new connection: [Errno -3] Temporary failure in name resolution'))

During handling of the above exception, another exception occurred:

Traceback (most recent call last):
  File "/home/airflow/.local/lib/python3.7/site-packages/airflow/operators/python.py", line 175, in execute
    return_value = self.execute_callable()
  File "/home/airflow/.local/lib/python3.7/site-packages/airflow/operators/python.py", line 192, in execute_callable
    return self.python_callable(*self.op_args, **self.op_kwargs)
  File "/opt/airflow/dags/ticker.py", line 25, in data_to_txt
    ticker = get_data()
  File "/opt/airflow/dags/ticker.py", line 16, in get_data
    company_list = listing_companies()
  File "/home/airflow/.local/lib/python3.7/site-packages/vnstock/stock.py", line 19, in listing_companies
    r = api_request(url)
  File "/home/airflow/.local/lib/python3.7/site-packages/vnstock/stock.py", line 387, in api_request
    r = requests.get(url, headers=headers).json()
  File "/home/airflow/.local/lib/python3.7/site-packages/requests/api.py", line 73, in get
    return request("get", url, params=params, **kwargs)
  File "/home/airflow/.local/lib/python3.7/site-packages/requests/api.py", line 59, in request
    return session.request(method=method, url=url, **kwargs)
  File "/home/airflow/.local/lib/python3.7/site-packages/requests/sessions.py", line 587, in request
    resp = self.send(prep, **send_kwargs)
  File "/home/airflow/.local/lib/python3.7/site-packages/requests/sessions.py", line 701, in send
    r = adapter.send(request, **kwargs)
  File "/home/airflow/.local/lib/python3.7/site-packages/requests/adapters.py", line 565, in send
    raise ConnectionError(e, request=request)
requests.exceptions.ConnectionError: HTTPSConnectionPool(host='fiin-core.ssi.com.vn', port=443): Max retries exceeded with url: /Master/GetListOrganization?language=vi (Caused by NewConnectionError('<urllib3.connection.HTTPSConnection object at 0x7f6905fa6390>: Failed to establish a new connection: [Errno -3] Temporary failure in name resolution'))
[2023-01-05T02:14:14.862+0000] {taskinstance.py:1327} INFO - Marking task as FAILED. dag_id=ticker_to_txt, task_id=ticker_to_txt, execution_date=20230105T021346, start_date=20230105T021404, end_date=20230105T021414
[2023-01-05T02:14:14.910+0000] {standard_task_runner.py:105} ERROR - Failed to execute job 182 for task ticker_to_txt (HTTPSConnectionPool(host='fiin-core.ssi.com.vn', port=443): Max retries exceeded with url: /Master/GetListOrganization?language=vi (Caused by NewConnectionError('<urllib3.connection.HTTPSConnection object at 0x7f6905fa6390>: Failed to establish a new connection: [Errno -3] Temporary failure in name resolution')); 79886)
[2023-01-05T02:14:14.956+0000] {local_task_job.py:159} INFO - Task exited with return code 1
[2023-01-05T02:14:14.980+0000] {taskinstance.py:2582} INFO - 0 downstream tasks scheduled from follow-on schedule check
