[2022-12-28T04:49:51.801+0000] {taskinstance.py:1087} INFO - Dependencies all met for <TaskInstance: new_table_and_data_import_dag_v1.get_cash_flow_data manual__2022-12-28T04:49:48.058459+00:00 [queued]>
[2022-12-28T04:49:51.811+0000] {taskinstance.py:1087} INFO - Dependencies all met for <TaskInstance: new_table_and_data_import_dag_v1.get_cash_flow_data manual__2022-12-28T04:49:48.058459+00:00 [queued]>
[2022-12-28T04:49:51.812+0000] {taskinstance.py:1283} INFO - 
--------------------------------------------------------------------------------
[2022-12-28T04:49:51.812+0000] {taskinstance.py:1284} INFO - Starting attempt 1 of 1
[2022-12-28T04:49:51.812+0000] {taskinstance.py:1285} INFO - 
--------------------------------------------------------------------------------
[2022-12-28T04:49:51.850+0000] {taskinstance.py:1304} INFO - Executing <Task(PythonOperator): get_cash_flow_data> on 2022-12-28 04:49:48.058459+00:00
[2022-12-28T04:49:51.856+0000] {standard_task_runner.py:55} INFO - Started process 585 to run task
[2022-12-28T04:49:51.859+0000] {standard_task_runner.py:82} INFO - Running: ['***', 'tasks', 'run', 'new_table_and_data_import_dag_v1', 'get_cash_flow_data', 'manual__2022-12-28T04:49:48.058459+00:00', '--job-id', '7', '--raw', '--subdir', 'DAGS_FOLDER/new_table_and_data_import_dag.py', '--cfg-path', '/tmp/tmpzbs3rug4']
[2022-12-28T04:49:51.861+0000] {standard_task_runner.py:83} INFO - Job 7: Subtask get_cash_flow_data
[2022-12-28T04:49:51.931+0000] {task_command.py:389} INFO - Running <TaskInstance: new_table_and_data_import_dag_v1.get_cash_flow_data manual__2022-12-28T04:49:48.058459+00:00 [running]> on host 016cb28b89a1
[2022-12-28T04:49:52.047+0000] {taskinstance.py:1513} INFO - Exporting the following env vars:
AIRFLOW_CTX_DAG_OWNER=***
AIRFLOW_CTX_DAG_ID=new_table_and_data_import_dag_v1
AIRFLOW_CTX_TASK_ID=get_cash_flow_data
AIRFLOW_CTX_EXECUTION_DATE=2022-12-28T04:49:48.058459+00:00
AIRFLOW_CTX_TRY_NUMBER=1
AIRFLOW_CTX_DAG_RUN_ID=manual__2022-12-28T04:49:48.058459+00:00
[2022-12-28T04:49:52.079+0000] {taskinstance.py:1772} ERROR - Task failed with exception
Traceback (most recent call last):
  File "/home/airflow/.local/lib/python3.7/site-packages/urllib3/connection.py", line 175, in _new_conn
    (self._dns_host, self.port), self.timeout, **extra_kw
  File "/home/airflow/.local/lib/python3.7/site-packages/urllib3/util/connection.py", line 72, in create_connection
    for res in socket.getaddrinfo(host, port, family, socket.SOCK_STREAM):
  File "/usr/local/lib/python3.7/socket.py", line 752, in getaddrinfo
    for res in _socket.getaddrinfo(host, port, family, type, proto, flags):
socket.gaierror: [Errno -3] Temporary failure in name resolution

During handling of the above exception, another exception occurred:

Traceback (most recent call last):
  File "/home/airflow/.local/lib/python3.7/site-packages/urllib3/connectionpool.py", line 710, in urlopen
    chunked=chunked,
  File "/home/airflow/.local/lib/python3.7/site-packages/urllib3/connectionpool.py", line 386, in _make_request
    self._validate_conn(conn)
  File "/home/airflow/.local/lib/python3.7/site-packages/urllib3/connectionpool.py", line 1042, in _validate_conn
    conn.connect()
  File "/home/airflow/.local/lib/python3.7/site-packages/urllib3/connection.py", line 358, in connect
    self.sock = conn = self._new_conn()
  File "/home/airflow/.local/lib/python3.7/site-packages/urllib3/connection.py", line 187, in _new_conn
    self, "Failed to establish a new connection: %s" % e
urllib3.exceptions.NewConnectionError: <urllib3.connection.HTTPSConnection object at 0x7fd8e8037c50>: Failed to establish a new connection: [Errno -3] Temporary failure in name resolution

During handling of the above exception, another exception occurred:

Traceback (most recent call last):
  File "/home/airflow/.local/lib/python3.7/site-packages/requests/adapters.py", line 499, in send
    timeout=timeout,
  File "/home/airflow/.local/lib/python3.7/site-packages/urllib3/connectionpool.py", line 788, in urlopen
    method, url, error=e, _pool=self, _stacktrace=sys.exc_info()[2]
  File "/home/airflow/.local/lib/python3.7/site-packages/urllib3/util/retry.py", line 592, in increment
    raise MaxRetryError(_pool, url, error or ResponseError(cause))
urllib3.exceptions.MaxRetryError: HTTPSConnectionPool(host='fiin-core.ssi.com.vn', port=443): Max retries exceeded with url: /Master/GetListOrganization?language=vi (Caused by NewConnectionError('<urllib3.connection.HTTPSConnection object at 0x7fd8e8037c50>: Failed to establish a new connection: [Errno -3] Temporary failure in name resolution'))

During handling of the above exception, another exception occurred:

Traceback (most recent call last):
  File "/home/airflow/.local/lib/python3.7/site-packages/airflow/operators/python.py", line 175, in execute
    return_value = self.execute_callable()
  File "/home/airflow/.local/lib/python3.7/site-packages/airflow/operators/python.py", line 192, in execute_callable
    return self.python_callable(*self.op_args, **self.op_kwargs)
  File "/opt/airflow/dags/new_table_and_data_import_dag.py", line 29, in get_cash_flow
    tickers = get_ticker_list()
  File "/opt/airflow/dags/new_table_and_data_import_dag.py", line 21, in get_ticker_list
    company_list = listing_companies()
  File "/home/airflow/.local/lib/python3.7/site-packages/vnstock/stock.py", line 19, in listing_companies
    r = api_request(url)
  File "/home/airflow/.local/lib/python3.7/site-packages/vnstock/stock.py", line 387, in api_request
    r = requests.get(url, headers=headers).json()
  File "/home/airflow/.local/lib/python3.7/site-packages/requests/api.py", line 73, in get
    return request("get", url, params=params, **kwargs)
  File "/home/airflow/.local/lib/python3.7/site-packages/requests/api.py", line 59, in request
    return session.request(method=method, url=url, **kwargs)
  File "/home/airflow/.local/lib/python3.7/site-packages/requests/sessions.py", line 587, in request
    resp = self.send(prep, **send_kwargs)
  File "/home/airflow/.local/lib/python3.7/site-packages/requests/sessions.py", line 701, in send
    r = adapter.send(request, **kwargs)
  File "/home/airflow/.local/lib/python3.7/site-packages/requests/adapters.py", line 565, in send
    raise ConnectionError(e, request=request)
requests.exceptions.ConnectionError: HTTPSConnectionPool(host='fiin-core.ssi.com.vn', port=443): Max retries exceeded with url: /Master/GetListOrganization?language=vi (Caused by NewConnectionError('<urllib3.connection.HTTPSConnection object at 0x7fd8e8037c50>: Failed to establish a new connection: [Errno -3] Temporary failure in name resolution'))
[2022-12-28T04:49:52.088+0000] {taskinstance.py:1327} INFO - Marking task as FAILED. dag_id=new_table_and_data_import_dag_v1, task_id=get_cash_flow_data, execution_date=20221228T044948, start_date=20221228T044951, end_date=20221228T044952
[2022-12-28T04:49:52.138+0000] {standard_task_runner.py:105} ERROR - Failed to execute job 7 for task get_cash_flow_data (HTTPSConnectionPool(host='fiin-core.ssi.com.vn', port=443): Max retries exceeded with url: /Master/GetListOrganization?language=vi (Caused by NewConnectionError('<urllib3.connection.HTTPSConnection object at 0x7fd8e8037c50>: Failed to establish a new connection: [Errno -3] Temporary failure in name resolution')); 585)
[2022-12-28T04:49:52.150+0000] {local_task_job.py:159} INFO - Task exited with return code 1
[2022-12-28T04:49:52.177+0000] {taskinstance.py:2582} INFO - 0 downstream tasks scheduled from follow-on schedule check
