[2022-12-26T04:05:44.592+0000] {taskinstance.py:1087} INFO - Dependencies all met for <TaskInstance: new_table_and_data_import_dag_v1.create_table scheduled__2022-12-25T00:00:00+00:00 [queued]>
[2022-12-26T04:05:44.600+0000] {taskinstance.py:1087} INFO - Dependencies all met for <TaskInstance: new_table_and_data_import_dag_v1.create_table scheduled__2022-12-25T00:00:00+00:00 [queued]>
[2022-12-26T04:05:44.600+0000] {taskinstance.py:1283} INFO - 
--------------------------------------------------------------------------------
[2022-12-26T04:05:44.601+0000] {taskinstance.py:1284} INFO - Starting attempt 1 of 1
[2022-12-26T04:05:44.601+0000] {taskinstance.py:1285} INFO - 
--------------------------------------------------------------------------------
[2022-12-26T04:05:44.640+0000] {taskinstance.py:1304} INFO - Executing <Task(PostgresOperator): create_table> on 2022-12-25 00:00:00+00:00
[2022-12-26T04:05:44.646+0000] {standard_task_runner.py:55} INFO - Started process 189 to run task
[2022-12-26T04:05:44.648+0000] {standard_task_runner.py:82} INFO - Running: ['***', 'tasks', 'run', 'new_table_and_data_import_dag_v1', 'create_table', 'scheduled__2022-12-25T00:00:00+00:00', '--job-id', '72', '--raw', '--subdir', 'DAGS_FOLDER/new_table_and_data_import_dag.py', '--cfg-path', '/tmp/tmpbg9opb6x']
[2022-12-26T04:05:44.650+0000] {standard_task_runner.py:83} INFO - Job 72: Subtask create_table
[2022-12-26T04:05:44.744+0000] {task_command.py:389} INFO - Running <TaskInstance: new_table_and_data_import_dag_v1.create_table scheduled__2022-12-25T00:00:00+00:00 [running]> on host 3a7da4d7a43a
[2022-12-26T04:05:45.056+0000] {taskinstance.py:1513} INFO - Exporting the following env vars:
AIRFLOW_CTX_DAG_OWNER=***
AIRFLOW_CTX_DAG_ID=new_table_and_data_import_dag_v1
AIRFLOW_CTX_TASK_ID=create_table
AIRFLOW_CTX_EXECUTION_DATE=2022-12-25T00:00:00+00:00
AIRFLOW_CTX_TRY_NUMBER=1
AIRFLOW_CTX_DAG_RUN_ID=scheduled__2022-12-25T00:00:00+00:00
[2022-12-26T04:05:45.057+0000] {sql.py:253} INFO - Executing: 
            CREATE TABLE IF NOT EXISTS test_table (
                ticker varchar(3),
                year integer,
                quarter integer,
                invest_cost integer,
                from_invest integer,
                from_financial integer,
                from_sale integer,
                free_cash_flow double precision,
                PRIMARY KEY (ticker, year, quarter),
                FOREIGN KEY (ticker) REFERENCES listing_companies (ticker)
            );
        
[2022-12-26T04:05:45.064+0000] {base.py:73} INFO - Using connection ID 'financial_database' for task execution.
[2022-12-26T04:05:45.286+0000] {base.py:73} INFO - Using connection ID 'financial_database' for task execution.
[2022-12-26T04:05:45.296+0000] {sql.py:364} INFO - Running statement: 
            CREATE TABLE IF NOT EXISTS test_table (
                ticker varchar(3),
                year integer,
                quarter integer,
                invest_cost integer,
                from_invest integer,
                from_financial integer,
                from_sale integer,
                free_cash_flow double precision,
                PRIMARY KEY (ticker, year, quarter),
                FOREIGN KEY (ticker) REFERENCES listing_companies (ticker)
            );
        , parameters: None
[2022-12-26T04:05:46.904+0000] {taskinstance.py:1772} ERROR - Task failed with exception
Traceback (most recent call last):
  File "/home/airflow/.local/lib/python3.7/site-packages/airflow/providers/common/sql/operators/sql.py", line 261, in execute
    return_last=self.return_last,
  File "/home/airflow/.local/lib/python3.7/site-packages/airflow/providers/common/sql/hooks/sql.py", line 338, in run
    self._run_command(cur, sql_statement, parameters)
  File "/home/airflow/.local/lib/python3.7/site-packages/airflow/providers/common/sql/hooks/sql.py", line 369, in _run_command
    cur.execute(sql_statement)
psycopg2.errors.UniqueViolation: duplicate key value violates unique constraint "pg_type_typname_nsp_index"
DETAIL:  Key (typname, typnamespace)=(test_table, 2200) already exists.

[2022-12-26T04:05:46.913+0000] {taskinstance.py:1327} INFO - Marking task as FAILED. dag_id=new_table_and_data_import_dag_v1, task_id=create_table, execution_date=20221225T000000, start_date=20221226T040544, end_date=20221226T040546
[2022-12-26T04:05:47.261+0000] {standard_task_runner.py:105} ERROR - Failed to execute job 72 for task create_table (duplicate key value violates unique constraint "pg_type_typname_nsp_index"
DETAIL:  Key (typname, typnamespace)=(test_table, 2200) already exists.
; 189)
[2022-12-26T04:05:47.307+0000] {local_task_job.py:159} INFO - Task exited with return code 1
[2022-12-26T04:05:47.450+0000] {taskinstance.py:2582} INFO - 0 downstream tasks scheduled from follow-on schedule check
