[2023-01-01T05:36:04.043+0000] {taskinstance.py:1087} INFO - Dependencies all met for <TaskInstance: import_to_test_table_v1.create_test_table manual__2023-01-01T05:35:51.666118+00:00 [queued]>
[2023-01-01T05:36:04.383+0000] {taskinstance.py:1087} INFO - Dependencies all met for <TaskInstance: import_to_test_table_v1.create_test_table manual__2023-01-01T05:35:51.666118+00:00 [queued]>
[2023-01-01T05:36:04.384+0000] {taskinstance.py:1283} INFO - 
--------------------------------------------------------------------------------
[2023-01-01T05:36:04.384+0000] {taskinstance.py:1284} INFO - Starting attempt 1 of 1
[2023-01-01T05:36:04.384+0000] {taskinstance.py:1285} INFO - 
--------------------------------------------------------------------------------
[2023-01-01T05:36:05.373+0000] {taskinstance.py:1304} INFO - Executing <Task(PostgresOperator): create_test_table> on 2023-01-01 05:35:51.666118+00:00
[2023-01-01T05:36:05.391+0000] {standard_task_runner.py:55} INFO - Started process 350 to run task
[2023-01-01T05:36:05.433+0000] {standard_task_runner.py:82} INFO - Running: ['***', 'tasks', 'run', 'import_to_test_table_v1', 'create_test_table', 'manual__2023-01-01T05:35:51.666118+00:00', '--job-id', '125', '--raw', '--subdir', 'DAGS_FOLDER/import_to_test_table.py', '--cfg-path', '/tmp/tmp0ltw3gla']
[2023-01-01T05:36:05.555+0000] {standard_task_runner.py:83} INFO - Job 125: Subtask create_test_table
[2023-01-01T05:36:06.355+0000] {task_command.py:389} INFO - Running <TaskInstance: import_to_test_table_v1.create_test_table manual__2023-01-01T05:35:51.666118+00:00 [running]> on host 9b696cbf6f55
[2023-01-01T05:36:08.040+0000] {taskinstance.py:1513} INFO - Exporting the following env vars:
AIRFLOW_CTX_DAG_OWNER=***
AIRFLOW_CTX_DAG_ID=import_to_test_table_v1
AIRFLOW_CTX_TASK_ID=create_test_table
AIRFLOW_CTX_EXECUTION_DATE=2023-01-01T05:35:51.666118+00:00
AIRFLOW_CTX_TRY_NUMBER=1
AIRFLOW_CTX_DAG_RUN_ID=manual__2023-01-01T05:35:51.666118+00:00
[2023-01-01T05:36:08.041+0000] {sql.py:253} INFO - Executing: 
            create table if not exists test_table (
                ticker varchar(3),
                year integer,
                quarter integer,
                invest_cost integer,
                from_invest integer,
                from_financial integer,
                from_sale integer,
                free_cash_flow double precision,
                PRIMARY KEY (ticker, year, quarter),
                FOREIGN KEY (ticker) REFERENCES listing_companies (ticker)
            )
        
[2023-01-01T05:36:08.059+0000] {base.py:73} INFO - Using connection ID 'financial_database' for task execution.
[2023-01-01T05:36:08.529+0000] {base.py:73} INFO - Using connection ID 'financial_database' for task execution.
[2023-01-01T05:36:09.079+0000] {sql.py:364} INFO - Running statement: 
            create table if not exists test_table (
                ticker varchar(3),
                year integer,
                quarter integer,
                invest_cost integer,
                from_invest integer,
                from_financial integer,
                from_sale integer,
                free_cash_flow double precision,
                PRIMARY KEY (ticker, year, quarter),
                FOREIGN KEY (ticker) REFERENCES listing_companies (ticker)
            )
        , parameters: None
[2023-01-01T05:36:18.348+0000] {taskinstance.py:1772} ERROR - Task failed with exception
Traceback (most recent call last):
  File "/home/airflow/.local/lib/python3.7/site-packages/airflow/providers/common/sql/operators/sql.py", line 261, in execute
    return_last=self.return_last,
  File "/home/airflow/.local/lib/python3.7/site-packages/airflow/providers/common/sql/hooks/sql.py", line 338, in run
    self._run_command(cur, sql_statement, parameters)
  File "/home/airflow/.local/lib/python3.7/site-packages/airflow/providers/common/sql/hooks/sql.py", line 369, in _run_command
    cur.execute(sql_statement)
psycopg2.errors.UniqueViolation: duplicate key value violates unique constraint "pg_type_typname_nsp_index"
DETAIL:  Key (typname, typnamespace)=(test_table, 2200) already exists.

[2023-01-01T05:36:18.355+0000] {taskinstance.py:1327} INFO - Marking task as FAILED. dag_id=import_to_test_table_v1, task_id=create_test_table, execution_date=20230101T053551, start_date=20230101T053604, end_date=20230101T053618
[2023-01-01T05:36:19.674+0000] {standard_task_runner.py:105} ERROR - Failed to execute job 125 for task create_test_table (duplicate key value violates unique constraint "pg_type_typname_nsp_index"
DETAIL:  Key (typname, typnamespace)=(test_table, 2200) already exists.
; 350)
[2023-01-01T05:36:19.691+0000] {local_task_job.py:159} INFO - Task exited with return code 1
[2023-01-01T05:36:19.716+0000] {taskinstance.py:2582} INFO - 0 downstream tasks scheduled from follow-on schedule check
