[2022-12-28T04:48:42.124+0000] {taskinstance.py:1087} INFO - Dependencies all met for <TaskInstance: new_table_and_data_import_dag_v1.create_table manual__2022-12-28T04:48:39.210919+00:00 [queued]>
[2022-12-28T04:48:42.132+0000] {taskinstance.py:1087} INFO - Dependencies all met for <TaskInstance: new_table_and_data_import_dag_v1.create_table manual__2022-12-28T04:48:39.210919+00:00 [queued]>
[2022-12-28T04:48:42.132+0000] {taskinstance.py:1283} INFO - 
--------------------------------------------------------------------------------
[2022-12-28T04:48:42.132+0000] {taskinstance.py:1284} INFO - Starting attempt 1 of 1
[2022-12-28T04:48:42.132+0000] {taskinstance.py:1285} INFO - 
--------------------------------------------------------------------------------
[2022-12-28T04:48:42.183+0000] {taskinstance.py:1304} INFO - Executing <Task(PostgresOperator): create_table> on 2022-12-28 04:48:39.210919+00:00
[2022-12-28T04:48:42.189+0000] {standard_task_runner.py:55} INFO - Started process 472 to run task
[2022-12-28T04:48:42.193+0000] {standard_task_runner.py:82} INFO - Running: ['***', 'tasks', 'run', 'new_table_and_data_import_dag_v1', 'create_table', 'manual__2022-12-28T04:48:39.210919+00:00', '--job-id', '5', '--raw', '--subdir', 'DAGS_FOLDER/new_table_and_data_import_dag.py', '--cfg-path', '/tmp/tmpr0dvataw']
[2022-12-28T04:48:42.194+0000] {standard_task_runner.py:83} INFO - Job 5: Subtask create_table
[2022-12-28T04:48:42.287+0000] {task_command.py:389} INFO - Running <TaskInstance: new_table_and_data_import_dag_v1.create_table manual__2022-12-28T04:48:39.210919+00:00 [running]> on host 016cb28b89a1
[2022-12-28T04:48:42.432+0000] {taskinstance.py:1513} INFO - Exporting the following env vars:
AIRFLOW_CTX_DAG_OWNER=***
AIRFLOW_CTX_DAG_ID=new_table_and_data_import_dag_v1
AIRFLOW_CTX_TASK_ID=create_table
AIRFLOW_CTX_EXECUTION_DATE=2022-12-28T04:48:39.210919+00:00
AIRFLOW_CTX_TRY_NUMBER=1
AIRFLOW_CTX_DAG_RUN_ID=manual__2022-12-28T04:48:39.210919+00:00
[2022-12-28T04:48:42.433+0000] {sql.py:253} INFO - Executing: 
            CREATE TABLE IF NOT EXISTS test_table (
                ticker varchar(3),
                year integer,
                quarter integer,
                invest_cost integer,
                from_invest integer,
                from_financial integer,
                from_sale integer,
                free_cash_flow double precision,
                PRIMARY KEY (ticker, year, quarter),
                FOREIGN KEY (ticker) REFERENCES listing_companies (ticker)
            );
        
[2022-12-28T04:48:42.442+0000] {base.py:73} INFO - Using connection ID 'financial_database' for task execution.
[2022-12-28T04:48:42.790+0000] {base.py:73} INFO - Using connection ID 'financial_database' for task execution.
[2022-12-28T04:48:42.834+0000] {sql.py:364} INFO - Running statement: 
            CREATE TABLE IF NOT EXISTS test_table (
                ticker varchar(3),
                year integer,
                quarter integer,
                invest_cost integer,
                from_invest integer,
                from_financial integer,
                from_sale integer,
                free_cash_flow double precision,
                PRIMARY KEY (ticker, year, quarter),
                FOREIGN KEY (ticker) REFERENCES listing_companies (ticker)
            );
        , parameters: None
[2022-12-28T04:48:45.131+0000] {taskinstance.py:1772} ERROR - Task failed with exception
Traceback (most recent call last):
  File "/home/airflow/.local/lib/python3.7/site-packages/airflow/providers/common/sql/operators/sql.py", line 261, in execute
    return_last=self.return_last,
  File "/home/airflow/.local/lib/python3.7/site-packages/airflow/providers/common/sql/hooks/sql.py", line 338, in run
    self._run_command(cur, sql_statement, parameters)
  File "/home/airflow/.local/lib/python3.7/site-packages/airflow/providers/common/sql/hooks/sql.py", line 369, in _run_command
    cur.execute(sql_statement)
psycopg2.errors.UndefinedTable: relation "listing_companies" does not exist

[2022-12-28T04:48:45.142+0000] {taskinstance.py:1327} INFO - Marking task as FAILED. dag_id=new_table_and_data_import_dag_v1, task_id=create_table, execution_date=20221228T044839, start_date=20221228T044842, end_date=20221228T044845
[2022-12-28T04:48:45.390+0000] {standard_task_runner.py:105} ERROR - Failed to execute job 5 for task create_table (relation "listing_companies" does not exist
; 472)
[2022-12-28T04:48:45.412+0000] {local_task_job.py:159} INFO - Task exited with return code 1
[2022-12-28T04:48:45.439+0000] {taskinstance.py:2582} INFO - 0 downstream tasks scheduled from follow-on schedule check
