[2022-12-28T04:45:58.928+0000] {taskinstance.py:1087} INFO - Dependencies all met for <TaskInstance: new_table_and_data_import_dag_v1.create_table manual__2022-12-28T04:45:49.702636+00:00 [queued]>
[2022-12-28T04:45:58.939+0000] {taskinstance.py:1087} INFO - Dependencies all met for <TaskInstance: new_table_and_data_import_dag_v1.create_table manual__2022-12-28T04:45:49.702636+00:00 [queued]>
[2022-12-28T04:45:58.939+0000] {taskinstance.py:1283} INFO - 
--------------------------------------------------------------------------------
[2022-12-28T04:45:58.939+0000] {taskinstance.py:1284} INFO - Starting attempt 1 of 1
[2022-12-28T04:45:58.940+0000] {taskinstance.py:1285} INFO - 
--------------------------------------------------------------------------------
[2022-12-28T04:45:58.990+0000] {taskinstance.py:1304} INFO - Executing <Task(PostgresOperator): create_table> on 2022-12-28 04:45:49.702636+00:00
[2022-12-28T04:45:58.996+0000] {standard_task_runner.py:55} INFO - Started process 218 to run task
[2022-12-28T04:45:58.999+0000] {standard_task_runner.py:82} INFO - Running: ['***', 'tasks', 'run', 'new_table_and_data_import_dag_v1', 'create_table', 'manual__2022-12-28T04:45:49.702636+00:00', '--job-id', '4', '--raw', '--subdir', 'DAGS_FOLDER/new_table_and_data_import_dag.py', '--cfg-path', '/tmp/tmpaskza858']
[2022-12-28T04:45:59.000+0000] {standard_task_runner.py:83} INFO - Job 4: Subtask create_table
[2022-12-28T04:45:59.093+0000] {task_command.py:389} INFO - Running <TaskInstance: new_table_and_data_import_dag_v1.create_table manual__2022-12-28T04:45:49.702636+00:00 [running]> on host 016cb28b89a1
[2022-12-28T04:45:59.325+0000] {taskinstance.py:1513} INFO - Exporting the following env vars:
AIRFLOW_CTX_DAG_OWNER=***
AIRFLOW_CTX_DAG_ID=new_table_and_data_import_dag_v1
AIRFLOW_CTX_TASK_ID=create_table
AIRFLOW_CTX_EXECUTION_DATE=2022-12-28T04:45:49.702636+00:00
AIRFLOW_CTX_TRY_NUMBER=1
AIRFLOW_CTX_DAG_RUN_ID=manual__2022-12-28T04:45:49.702636+00:00
[2022-12-28T04:45:59.326+0000] {sql.py:253} INFO - Executing: 
            CREATE TABLE IF NOT EXISTS test_table (
                ticker varchar(3),
                year integer,
                quarter integer,
                invest_cost integer,
                from_invest integer,
                from_financial integer,
                from_sale integer,
                free_cash_flow double precision,
                PRIMARY KEY (ticker, year, quarter),
                FOREIGN KEY (ticker) REFERENCES listing_companies (ticker)
            );
        
[2022-12-28T04:45:59.342+0000] {taskinstance.py:1772} ERROR - Task failed with exception
Traceback (most recent call last):
  File "/home/airflow/.local/lib/python3.7/site-packages/airflow/providers/common/sql/operators/sql.py", line 254, in execute
    hook = self.get_db_hook()
  File "/home/airflow/.local/lib/python3.7/site-packages/airflow/providers/common/sql/operators/sql.py", line 179, in get_db_hook
    return self._hook
  File "/home/airflow/.local/lib/python3.7/site-packages/cached_property.py", line 36, in __get__
    value = obj.__dict__[self.func.__name__] = self.func(obj)
  File "/home/airflow/.local/lib/python3.7/site-packages/airflow/providers/common/sql/operators/sql.py", line 141, in _hook
    conn = BaseHook.get_connection(self.conn_id)
  File "/home/airflow/.local/lib/python3.7/site-packages/airflow/hooks/base.py", line 72, in get_connection
    conn = Connection.get_connection_from_secrets(conn_id)
  File "/home/airflow/.local/lib/python3.7/site-packages/airflow/models/connection.py", line 432, in get_connection_from_secrets
    raise AirflowNotFoundException(f"The conn_id `{conn_id}` isn't defined")
airflow.exceptions.AirflowNotFoundException: The conn_id `financial_database` isn't defined
[2022-12-28T04:45:59.345+0000] {taskinstance.py:1327} INFO - Marking task as FAILED. dag_id=new_table_and_data_import_dag_v1, task_id=create_table, execution_date=20221228T044549, start_date=20221228T044558, end_date=20221228T044559
[2022-12-28T04:45:59.399+0000] {standard_task_runner.py:105} ERROR - Failed to execute job 4 for task create_table (The conn_id `financial_database` isn't defined; 218)
[2022-12-28T04:45:59.410+0000] {local_task_job.py:159} INFO - Task exited with return code 1
[2022-12-28T04:45:59.445+0000] {taskinstance.py:2582} INFO - 0 downstream tasks scheduled from follow-on schedule check
